
XXXXXXXXXXXXXXXXXXXXXXXXXXXXXXXXXXXXXXXXXXXX 
Date:  gio 20 ott 2022, 18.14.37, CEST
Directory:  /ceph/hpc/home/eudavider/repository/DynamicHead
Nodelist:  gn[25,27]
Number of nodes:  2
Ntasks per node:  1
NGPUs per node:  4
CUDA_VISIBLE_DEVICES:  0,1,2,3
TORCH_DEVICE_COUNT:  4
SLURM_MASTER_PORT:  14192
SLURM_MASTER_NODE:  gn25
SLURM_MASTER_ADDR:  gn25
SLURM_MASTER_URL:  tcp://gn25:14192
--------------------------------------------- 
MODEL_NUM_GPUS:  4
MODEL_NUM_MACHINES:  2
MODEL_BATCH_SIZE:  40
MODEL_MAX_ITER:  72000
XXXXXXXXXXXXXXXXXXXXXXXXXXXXXXXXXXXXXXXXXXXXX 

srun: error: WARNING: Multiple leaf switches contain nodes: gn[01-60]
[nltk_data] Downloading package omw-1.4 to
[nltk_data]     /ceph/hpc/home/eudavider/nltk_data...
[nltk_data]   Package omw-1.4 is already up-to-date!
[nltk_data] Downloading package wordnet to
[nltk_data]     /ceph/hpc/home/eudavider/nltk_data...
[nltk_data]   Package wordnet is already up-to-date!
Command Line Args: Namespace(config_file='./configs/COCO/dh/dh_r50_fpn_COCO_train.yaml', resume=False, eval_only=False, num_gpus=4, num_machines=2, machine_rank=0, dist_url='tcp://gn25:14192', opts=['SOLVER.IMS_PER_BATCH', '40', 'SOLVER.MAX_ITER', '72000'])
[nltk_data] Downloading package omw-1.4 to
[nltk_data]     /ceph/hpc/home/eudavider/nltk_data...
[nltk_data]   Package omw-1.4 is already up-to-date!
[nltk_data] Downloading package wordnet to
[nltk_data]     /ceph/hpc/home/eudavider/nltk_data...
[nltk_data]   Package wordnet is already up-to-date!
Command Line Args: Namespace(config_file='./configs/COCO/dh/dh_r50_fpn_COCO_train.yaml', resume=False, eval_only=False, num_gpus=4, num_machines=2, machine_rank=1, dist_url='tcp://gn25:14192', opts=['SOLVER.IMS_PER_BATCH', '40', 'SOLVER.MAX_ITER', '72000'])
Traceback (most recent call last):
  File "/ceph/hpc/scratch/user/eudavider/repository/DynamicHead/train_net.py", line 344, in <module>
    launch(
  File "/ceph/hpc/home/eudavider/.local/lib/python3.9/site-packages/detectron2/engine/launch.py", line 67, in launch
    mp.spawn(
  File "/ceph/hpc/home/eudavider/.conda/envs/dynamicHead/lib/python3.9/site-packages/torch/multiprocessing/spawn.py", line 230, in spawn
    return start_processes(fn, args, nprocs, join, daemon, start_method='spawn')
  File "/ceph/hpc/home/eudavider/.conda/envs/dynamicHead/lib/python3.9/site-packages/torch/multiprocessing/spawn.py", line 188, in start_processes
    while not context.join():
  File "/ceph/hpc/home/eudavider/.conda/envs/dynamicHead/lib/python3.9/site-packages/torch/multiprocessing/spawn.py", line 150, in join
    raise ProcessRaisedException(msg, error_index, failed_process.pid)
torch.multiprocessing.spawn.ProcessRaisedException: 

-- Process 1 terminated with the following error:
Traceback (most recent call last):
  File "/ceph/hpc/home/eudavider/.conda/envs/dynamicHead/lib/python3.9/site-packages/torch/multiprocessing/spawn.py", line 59, in _wrap
    fn(i, *args)
  File "/ceph/hpc/home/eudavider/.local/lib/python3.9/site-packages/detectron2/engine/launch.py", line 126, in _distributed_worker
    main_func(*args)
  File "/ceph/hpc/scratch/user/eudavider/repository/DynamicHead/train_net.py", line 307, in main
    cfg = setup(args)
  File "/ceph/hpc/scratch/user/eudavider/repository/DynamicHead/train_net.py", line 299, in setup
    cfg.merge_from_file(args.config_file)
  File "/ceph/hpc/home/eudavider/.local/lib/python3.9/site-packages/detectron2/config/config.py", line 45, in merge_from_file
    assert PathManager.isfile(cfg_filename), f"Config file '{cfg_filename}' does not exist!"
AssertionError: Config file './configs/COCO/dh/dh_r50_fpn_COCO_train.yaml' does not exist!

Traceback (most recent call last):
  File "/ceph/hpc/scratch/user/eudavider/repository/DynamicHead/train_net.py", line 344, in <module>
    launch(
  File "/ceph/hpc/home/eudavider/.local/lib/python3.9/site-packages/detectron2/engine/launch.py", line 67, in launch
    mp.spawn(
  File "/ceph/hpc/home/eudavider/.conda/envs/dynamicHead/lib/python3.9/site-packages/torch/multiprocessing/spawn.py", line 230, in spawn
    return start_processes(fn, args, nprocs, join, daemon, start_method='spawn')
  File "/ceph/hpc/home/eudavider/.conda/envs/dynamicHead/lib/python3.9/site-packages/torch/multiprocessing/spawn.py", line 188, in start_processes
    while not context.join():
  File "/ceph/hpc/home/eudavider/.conda/envs/dynamicHead/lib/python3.9/site-packages/torch/multiprocessing/spawn.py", line 150, in join
    raise ProcessRaisedException(msg, error_index, failed_process.pid)
torch.multiprocessing.spawn.ProcessRaisedException: 

-- Process 3 terminated with the following error:
Traceback (most recent call last):
  File "/ceph/hpc/home/eudavider/.conda/envs/dynamicHead/lib/python3.9/site-packages/torch/multiprocessing/spawn.py", line 59, in _wrap
    fn(i, *args)
  File "/ceph/hpc/home/eudavider/.local/lib/python3.9/site-packages/detectron2/engine/launch.py", line 126, in _distributed_worker
    main_func(*args)
  File "/ceph/hpc/scratch/user/eudavider/repository/DynamicHead/train_net.py", line 307, in main
    cfg = setup(args)
  File "/ceph/hpc/scratch/user/eudavider/repository/DynamicHead/train_net.py", line 299, in setup
    cfg.merge_from_file(args.config_file)
  File "/ceph/hpc/home/eudavider/.local/lib/python3.9/site-packages/detectron2/config/config.py", line 45, in merge_from_file
    assert PathManager.isfile(cfg_filename), f"Config file '{cfg_filename}' does not exist!"
AssertionError: Config file './configs/COCO/dh/dh_r50_fpn_COCO_train.yaml' does not exist!

srun: error: gn25: task 0: Exited with exit code 1
srun: error: gn27: task 1: Exited with exit code 1


Job done.
Date:  gio 20 ott 2022, 18.16.35, CEST
